Traceback (most recent call last):
  File "/Users/dchege711/anaconda3/lib/python3.6/site-packages/urllib3/connection.py", line 159, in _new_conn
    (self._dns_host, self.port), self.timeout, **extra_kw)
  File "/Users/dchege711/anaconda3/lib/python3.6/site-packages/urllib3/util/connection.py", line 57, in create_connection
    for res in socket.getaddrinfo(host, port, family, socket.SOCK_STREAM):
  File "/Users/dchege711/anaconda3/lib/python3.6/socket.py", line 745, in getaddrinfo
    for res in _socket.getaddrinfo(host, port, family, type, proto, flags):
socket.gaierror: [Errno 8] nodename nor servname provided, or not known

During handling of the above exception, another exception occurred:

Traceback (most recent call last):
  File "/Users/dchege711/anaconda3/lib/python3.6/site-packages/urllib3/connectionpool.py", line 600, in urlopen
    chunked=chunked)
  File "/Users/dchege711/anaconda3/lib/python3.6/site-packages/urllib3/connectionpool.py", line 354, in _make_request
    conn.request(method, url, **httplib_request_kw)
  File "/Users/dchege711/anaconda3/lib/python3.6/http/client.py", line 1239, in request
    self._send_request(method, url, body, headers, encode_chunked)
  File "/Users/dchege711/anaconda3/lib/python3.6/http/client.py", line 1285, in _send_request
    self.endheaders(body, encode_chunked=encode_chunked)
  File "/Users/dchege711/anaconda3/lib/python3.6/http/client.py", line 1234, in endheaders
    self._send_output(message_body, encode_chunked=encode_chunked)
  File "/Users/dchege711/anaconda3/lib/python3.6/http/client.py", line 1026, in _send_output
    self.send(msg)
  File "/Users/dchege711/anaconda3/lib/python3.6/http/client.py", line 964, in send
    self.connect()
  File "/Users/dchege711/anaconda3/lib/python3.6/site-packages/urllib3/connection.py", line 181, in connect
    conn = self._new_conn()
  File "/Users/dchege711/anaconda3/lib/python3.6/site-packages/urllib3/connection.py", line 168, in _new_conn
    self, "Failed to establish a new connection: %s" % e)
urllib3.exceptions.NewConnectionError: <urllib3.connection.HTTPConnection object at 0x1081a2278>: Failed to establish a new connection: [Errno 8] nodename nor servname provided, or not known

During handling of the above exception, another exception occurred:

Traceback (most recent call last):
  File "/Users/dchege711/anaconda3/lib/python3.6/site-packages/requests/adapters.py", line 449, in send
    timeout=timeout
  File "/Users/dchege711/anaconda3/lib/python3.6/site-packages/urllib3/connectionpool.py", line 638, in urlopen
    _stacktrace=sys.exc_info()[2])
  File "/Users/dchege711/anaconda3/lib/python3.6/site-packages/urllib3/util/retry.py", line 398, in increment
    raise MaxRetryError(_pool, url, error or ResponseError(cause))
urllib3.exceptions.MaxRetryError: HTTPConnectionPool(host='ws.audioscrobbler.com', port=80): Max retries exceeded with url: /2.0/?method=user.gettoptracks&user=dchege711&period=7day&api_key=24ede29990a304d6edd31c3fc722e018&limit=600&format=json (Caused by NewConnectionError('<urllib3.connection.HTTPConnection object at 0x1081a2278>: Failed to establish a new connection: [Errno 8] nodename nor servname provided, or not known',))

During handling of the above exception, another exception occurred:

Traceback (most recent call last):
  File "music_chart.py", line 160, in <module>
    tracks = fetch_top_tracks()
  File "music_chart.py", line 63, in fetch_top_tracks
    res_json = sess.get(BASE_URL, params=get_params).json()
  File "/Users/dchege711/anaconda3/lib/python3.6/site-packages/requests/sessions.py", line 546, in get
    return self.request('GET', url, **kwargs)
  File "/Users/dchege711/anaconda3/lib/python3.6/site-packages/requests/sessions.py", line 533, in request
    resp = self.send(prep, **send_kwargs)
  File "/Users/dchege711/anaconda3/lib/python3.6/site-packages/requests/sessions.py", line 646, in send
    r = adapter.send(request, **kwargs)
  File "/Users/dchege711/anaconda3/lib/python3.6/site-packages/requests/adapters.py", line 516, in send
    raise ConnectionError(e, request=request)
requests.exceptions.ConnectionError: HTTPConnectionPool(host='ws.audioscrobbler.com', port=80): Max retries exceeded with url: /2.0/?method=user.gettoptracks&user=dchege711&period=7day&api_key=24ede29990a304d6edd31c3fc722e018&limit=600&format=json (Caused by NewConnectionError('<urllib3.connection.HTTPConnection object at 0x1081a2278>: Failed to establish a new connection: [Errno 8] nodename nor servname provided, or not known',))
